<?xml version="1.0"?>
<robot xmlns:xacro="http://www.ros.org/wiki/xacro"  name="robot">

    <xacro:include filename="inertial_macros.xacro"/>

    <material name ="white">
        <color rgba="1 1 1 1"/>
    </material>

    <material name = "Orange">
        <color rgba="1 0.3 0.1 1"/>
    </material>

    <material name = "blue">
        <color rgba="0.2 0.2 1 1"/>
    </material>

    <material name ="black">
        <color rgba ="0 0 0 1"/>
    </material>
    <!-- Base Link -->
    <link name="base_link">

    </link>

    <!--Base Footprint Link-->
    
    <joint name="base_footprint_joint" type="fixed">
        <origin xyz="0.0 0.0 0.0" rpy="0.0 0.0 0.0"/>
        <parent link="base_link"/>
        <child link="base_footprint"/>
    </joint>

    <link name="base_footprint">
    </link>

    <!-- Chassis joint  -->
    
    <joint name ="chassis_joint" type="fixed">
        <parent link="base_link"/>
        <child link="chassis"/>
        <origin xyz = "-0.1 0 0"/>
    </joint>

    <!-- Chassis Link -->
    <link name= "chassis">
        <visual>
            <origin xyz="0.165 0 0.075"/>
            <geometry>
                <box size="0.418 0.352 0.095"/>
                <material name ="white"/>
            </geometry>
        </visual>
        <collision>
            <origin xyz="0.15 0 0.075"/>
            <geometry>
                <box size="0.418 0.352 0.95"/>
                <material name ="white"/>
            </geometry>
        </collision>
        <xacro:inertial_box mass="0.5" x="0.3" y="0.3" z="0.15">
            <origin xyz="0.15 0 0.075" rpy="0 0 0"/>
        </xacro:inertial_box>
        
    </link>

    <gazebo reference="chassis">
        <material>Gazebo/Red</material>
    </gazebo>


    <!-- Left Wheel Link -->

    <joint name="left_wheel_joint" type="continuous">
        <origin xyz="0 0.200 0" rpy="-${pi/2} 0.0 0.0"/>
        <parent link="base_link"/>
        <child link="left_wheel"/>
        <axis xyz="0.0 0.0 1"/>
    </joint>

    <link name="left_wheel">
        <visual name="">
            <origin xyz="0.0 0.0 0.0" rpy="0.0 0.0 0.0"/>
            <geometry>
                <cylinder radius="0.0325" length="0.026"/>
            </geometry>
            <material name="blue"/>
        </visual>
        <collision>
            <origin xyz="0.0 0.0 0.0" rpy="0.0 0.0 0.0"/>
            <geometry>
                <cylinder radius="0.0325" length="0.026"/>
            </geometry>
        </collision>
        <xacro:inertial_cylinder mass="0.1" length="0.026" radius="0.0325">
            <origin xyz="0 0 0" rpy="0 0 0"/>
        </xacro:inertial_cylinder>
    </link>

    <gazebo reference="left_wheel">
        <material>Gazebo/Blue</material>
    </gazebo>

    <!-- Right Wheel Link -->

    <joint name="right_wheel_joint" type="continuous">
        <origin xyz="0 -0.200 0" rpy="${pi/2} 0.0 0.0"/>
        <parent link="base_link"/>
        <child link="right_wheel"/>
        <axis xyz="0.0 0.0 -1"/>
    </joint>

    <link name="right_wheel">
        <visual name="">
            <origin xyz="0.0 0.0 0.0" rpy="0.0 0.0 0.0"/>
            <geometry>
                <cylinder radius="0.0325" length="0.026"/>
            </geometry>
            <material name="blue"/>
        </visual>
        <collision>
            <origin xyz="0.0 0.0 0.0" rpy="0.0 0.0 0.0"/>
            <geometry>
                <cylinder radius="0.05" length="0.04"/>
            </geometry>           
        </collision>
        <xacro:inertial_cylinder mass="0.1" length="0.026" radius="0.0325">
            <origin xyz="0 0 0" rpy="0 0 0"/>
        </xacro:inertial_cylinder>
    </link>

    <gazebo reference="right_wheel">
        <material>Gazebo/Blue</material>
    </gazebo>
    
    <!-- Caster wheel -->

    <joint name="caster_wheel_joint" type="fixed">
        <origin xyz="0.325 0.0 0.0" />
        <parent link="chassis"/>
        <child link="caster_wheel"/>
    </joint>

    <link name="caster_wheel">

        <visual name="">
            <geometry>
                    <sphere radius="0.0325"/>
            </geometry>
            <material name="black"/>
        </visual>
        <collision>
            <geometry>
                    <sphere radius="0.0325"/>
            </geometry>
        </collision>
        <xacro:inertial_sphere mass="0.1" radius="0.0325">
            <origin xyz="0 0 0" rpy="0 0 0"/>
        </xacro:inertial_sphere>
    </link>

    <gazebo reference="caster_wheel">
        <material>Gazebo/Black</material>
        <mu1 value="0.0001"/>
        <mu2 value="0.0001"/>
    </gazebo>

</robot>